2018-10-03 09:32:54,294 ERROR: Exception on /explore [GET] [in /home/mmesas/Documentos/aprendiendo/programacion/flask_/microblog/venv/lib/python3.6/site-packages/flask/app.py:1761]
Traceback (most recent call last):
  File "/home/mmesas/Documentos/aprendiendo/programacion/flask_/microblog/venv/lib/python3.6/site-packages/sqlalchemy/sql/elements.py", line 684, in __getattr__
    return getattr(self.comparator, key)
AttributeError: 'Comparator' object has no attribute 'all'

During handling of the above exception, another exception occurred:

Traceback (most recent call last):
  File "/home/mmesas/Documentos/aprendiendo/programacion/flask_/microblog/venv/lib/python3.6/site-packages/flask/app.py", line 2292, in wsgi_app
    response = self.full_dispatch_request()
  File "/home/mmesas/Documentos/aprendiendo/programacion/flask_/microblog/venv/lib/python3.6/site-packages/flask/app.py", line 1815, in full_dispatch_request
    rv = self.handle_user_exception(e)
  File "/home/mmesas/Documentos/aprendiendo/programacion/flask_/microblog/venv/lib/python3.6/site-packages/flask/app.py", line 1718, in handle_user_exception
    reraise(exc_type, exc_value, tb)
  File "/home/mmesas/Documentos/aprendiendo/programacion/flask_/microblog/venv/lib/python3.6/site-packages/flask/_compat.py", line 35, in reraise
    raise value
  File "/home/mmesas/Documentos/aprendiendo/programacion/flask_/microblog/venv/lib/python3.6/site-packages/flask/app.py", line 1813, in full_dispatch_request
    rv = self.dispatch_request()
  File "/home/mmesas/Documentos/aprendiendo/programacion/flask_/microblog/venv/lib/python3.6/site-packages/flask/app.py", line 1799, in dispatch_request
    return self.view_functions[rule.endpoint](**req.view_args)
  File "/home/mmesas/Documentos/aprendiendo/programacion/flask_/microblog/venv/lib/python3.6/site-packages/flask_login/utils.py", line 261, in decorated_view
    return func(*args, **kwargs)
  File "/home/mmesas/Documentos/aprendiendo/programacion/flask_/microblog/app/routes.py", line 154, in explore
    posts = Post.query.order_by(Post.timestamp.desc().all())
  File "/home/mmesas/Documentos/aprendiendo/programacion/flask_/microblog/venv/lib/python3.6/site-packages/sqlalchemy/sql/elements.py", line 690, in __getattr__
    key)
AttributeError: Neither 'UnaryExpression' object nor 'Comparator' object has an attribute 'all'
2018-10-03 09:34:32,582 INFO: Microblog startup [in /home/mmesas/Documentos/aprendiendo/programacion/flask_/microblog/app/__init__.py:57]
2018-10-03 15:55:43,544 INFO: Microblog startup [in /home/mmesas/Documentos/aprendiendo/programacion/flask_/microblog/app/__init__.py:57]
2018-10-03 15:57:07,326 INFO: Microblog startup [in /home/mmesas/Documentos/aprendiendo/programacion/flask_/microblog/app/__init__.py:57]
2018-10-03 15:57:16,118 ERROR: Exception on / [GET] [in /home/mmesas/Documentos/aprendiendo/programacion/flask_/microblog/venv/lib/python3.6/site-packages/flask/app.py:1761]
Traceback (most recent call last):
  File "/home/mmesas/Documentos/aprendiendo/programacion/flask_/microblog/venv/lib/python3.6/site-packages/flask/app.py", line 2292, in wsgi_app
    response = self.full_dispatch_request()
  File "/home/mmesas/Documentos/aprendiendo/programacion/flask_/microblog/venv/lib/python3.6/site-packages/flask/app.py", line 1815, in full_dispatch_request
    rv = self.handle_user_exception(e)
  File "/home/mmesas/Documentos/aprendiendo/programacion/flask_/microblog/venv/lib/python3.6/site-packages/flask/app.py", line 1718, in handle_user_exception
    reraise(exc_type, exc_value, tb)
  File "/home/mmesas/Documentos/aprendiendo/programacion/flask_/microblog/venv/lib/python3.6/site-packages/flask/_compat.py", line 35, in reraise
    raise value
  File "/home/mmesas/Documentos/aprendiendo/programacion/flask_/microblog/venv/lib/python3.6/site-packages/flask/app.py", line 1813, in full_dispatch_request
    rv = self.dispatch_request()
  File "/home/mmesas/Documentos/aprendiendo/programacion/flask_/microblog/venv/lib/python3.6/site-packages/flask/app.py", line 1799, in dispatch_request
    return self.view_functions[rule.endpoint](**req.view_args)
  File "/home/mmesas/Documentos/aprendiendo/programacion/flask_/microblog/venv/lib/python3.6/site-packages/flask_login/utils.py", line 261, in decorated_view
    return func(*args, **kwargs)
  File "/home/mmesas/Documentos/aprendiendo/programacion/flask_/microblog/app/routes.py", line 40, in index
    posts = current_user.followed_post().paginate(
  File "/home/mmesas/Documentos/aprendiendo/programacion/flask_/microblog/venv/lib/python3.6/site-packages/werkzeug/local.py", line 347, in __getattr__
    return getattr(self._get_current_object(), name)
AttributeError: 'User' object has no attribute 'followed_post'
2018-10-03 15:58:20,952 INFO: Microblog startup [in /home/mmesas/Documentos/aprendiendo/programacion/flask_/microblog/app/__init__.py:57]
2018-10-03 16:00:17,505 ERROR: Exception on /explore [GET] [in /home/mmesas/Documentos/aprendiendo/programacion/flask_/microblog/venv/lib/python3.6/site-packages/flask/app.py:1761]
Traceback (most recent call last):
  File "/home/mmesas/Documentos/aprendiendo/programacion/flask_/microblog/venv/lib/python3.6/site-packages/flask/app.py", line 2292, in wsgi_app
    response = self.full_dispatch_request()
  File "/home/mmesas/Documentos/aprendiendo/programacion/flask_/microblog/venv/lib/python3.6/site-packages/flask/app.py", line 1815, in full_dispatch_request
    rv = self.handle_user_exception(e)
  File "/home/mmesas/Documentos/aprendiendo/programacion/flask_/microblog/venv/lib/python3.6/site-packages/flask/app.py", line 1718, in handle_user_exception
    reraise(exc_type, exc_value, tb)
  File "/home/mmesas/Documentos/aprendiendo/programacion/flask_/microblog/venv/lib/python3.6/site-packages/flask/_compat.py", line 35, in reraise
    raise value
  File "/home/mmesas/Documentos/aprendiendo/programacion/flask_/microblog/venv/lib/python3.6/site-packages/flask/app.py", line 1813, in full_dispatch_request
    rv = self.dispatch_request()
  File "/home/mmesas/Documentos/aprendiendo/programacion/flask_/microblog/venv/lib/python3.6/site-packages/flask/app.py", line 1799, in dispatch_request
    return self.view_functions[rule.endpoint](**req.view_args)
  File "/home/mmesas/Documentos/aprendiendo/programacion/flask_/microblog/venv/lib/python3.6/site-packages/flask_login/utils.py", line 261, in decorated_view
    return func(*args, **kwargs)
  File "/home/mmesas/Documentos/aprendiendo/programacion/flask_/microblog/app/routes.py", line 159, in explore
    page, app.config['POSTS_PER_PAGE'], False)
KeyError: 'POSTS_PER_PAGE'
2018-10-03 16:00:45,000 INFO: Microblog startup [in /home/mmesas/Documentos/aprendiendo/programacion/flask_/microblog/app/__init__.py:57]
2018-10-03 16:01:14,599 ERROR: Exception on /index [GET] [in /home/mmesas/Documentos/aprendiendo/programacion/flask_/microblog/venv/lib/python3.6/site-packages/flask/app.py:1761]
Traceback (most recent call last):
  File "/home/mmesas/Documentos/aprendiendo/programacion/flask_/microblog/venv/lib/python3.6/site-packages/flask/app.py", line 2292, in wsgi_app
    response = self.full_dispatch_request()
  File "/home/mmesas/Documentos/aprendiendo/programacion/flask_/microblog/venv/lib/python3.6/site-packages/flask/app.py", line 1815, in full_dispatch_request
    rv = self.handle_user_exception(e)
  File "/home/mmesas/Documentos/aprendiendo/programacion/flask_/microblog/venv/lib/python3.6/site-packages/flask/app.py", line 1718, in handle_user_exception
    reraise(exc_type, exc_value, tb)
  File "/home/mmesas/Documentos/aprendiendo/programacion/flask_/microblog/venv/lib/python3.6/site-packages/flask/_compat.py", line 35, in reraise
    raise value
  File "/home/mmesas/Documentos/aprendiendo/programacion/flask_/microblog/venv/lib/python3.6/site-packages/flask/app.py", line 1813, in full_dispatch_request
    rv = self.dispatch_request()
  File "/home/mmesas/Documentos/aprendiendo/programacion/flask_/microblog/venv/lib/python3.6/site-packages/flask/app.py", line 1799, in dispatch_request
    return self.view_functions[rule.endpoint](**req.view_args)
  File "/home/mmesas/Documentos/aprendiendo/programacion/flask_/microblog/venv/lib/python3.6/site-packages/flask_login/utils.py", line 261, in decorated_view
    return func(*args, **kwargs)
  File "/home/mmesas/Documentos/aprendiendo/programacion/flask_/microblog/app/routes.py", line 41, in index
    page, app.config['POST_PER_PAGE'], False)
KeyError: 'POST_PER_PAGE'
